[2025-03-01T20:45:03.576+0000] {taskinstance.py:1125} INFO - Dependencies all met for dep_context=non-requeueable deps ti=<TaskInstance: api_to_db_dag.save_station_details_information scheduled__2025-03-01T20:30:00+00:00 [queued]>
[2025-03-01T20:45:03.583+0000] {taskinstance.py:1125} INFO - Dependencies all met for dep_context=requeueable deps ti=<TaskInstance: api_to_db_dag.save_station_details_information scheduled__2025-03-01T20:30:00+00:00 [queued]>
[2025-03-01T20:45:03.584+0000] {taskinstance.py:1331} INFO - Starting attempt 1 of 1
[2025-03-01T20:45:03.592+0000] {taskinstance.py:1350} INFO - Executing <Task(PythonOperator): save_station_details_information> on 2025-03-01 20:30:00+00:00
[2025-03-01T20:45:03.595+0000] {standard_task_runner.py:57} INFO - Started process 1780 to run task
[2025-03-01T20:45:03.598+0000] {standard_task_runner.py:84} INFO - Running: ['***', 'tasks', 'run', 'api_to_db_dag', 'save_station_details_information', 'scheduled__2025-03-01T20:30:00+00:00', '--job-id', '383', '--raw', '--subdir', 'DAGS_FOLDER/dag.py', '--cfg-path', '/tmp/tmptqr6a42n']
[2025-03-01T20:45:03.601+0000] {standard_task_runner.py:85} INFO - Job 383: Subtask save_station_details_information
[2025-03-01T20:45:03.651+0000] {task_command.py:410} INFO - Running <TaskInstance: api_to_db_dag.save_station_details_information scheduled__2025-03-01T20:30:00+00:00 [running]> on host 7d0564f8eb8b
[2025-03-01T20:45:03.703+0000] {taskinstance.py:1570} INFO - Exporting env vars: AIRFLOW_CTX_DAG_OWNER='***' AIRFLOW_CTX_DAG_ID='api_to_db_dag' AIRFLOW_CTX_TASK_ID='save_station_details_information' AIRFLOW_CTX_EXECUTION_DATE='2025-03-01T20:30:00+00:00' AIRFLOW_CTX_TRY_NUMBER='1' AIRFLOW_CTX_DAG_RUN_ID='scheduled__2025-03-01T20:30:00+00:00'
[2025-03-01T20:45:03.704+0000] {taskinstance.py:1847} ERROR - Task failed with exception
Traceback (most recent call last):
  File "/home/airflow/.local/lib/python3.7/site-packages/airflow/operators/python.py", line 181, in execute
    return_value = self.execute_callable()
  File "/home/airflow/.local/lib/python3.7/site-packages/airflow/operators/python.py", line 198, in execute_callable
    return self.python_callable(*self.op_args, **self.op_kwargs)
TypeError: save_to_datalake() missing 1 required positional argument: 'directory_path'
[2025-03-01T20:45:03.709+0000] {taskinstance.py:1373} INFO - Marking task as FAILED. dag_id=api_to_db_dag, task_id=save_station_details_information, execution_date=20250301T203000, start_date=20250301T204503, end_date=20250301T204503
[2025-03-01T20:45:03.715+0000] {standard_task_runner.py:109} ERROR - Failed to execute job 383 for task save_station_details_information (save_to_datalake() missing 1 required positional argument: 'directory_path'; 1780)
[2025-03-01T20:45:03.735+0000] {local_task_job_runner.py:232} INFO - Task exited with return code 1
[2025-03-01T20:45:03.762+0000] {taskinstance.py:2674} INFO - 0 downstream tasks scheduled from follow-on schedule check
