[2025-02-28T14:13:45.815+0000] {taskinstance.py:1125} INFO - Dependencies all met for dep_context=non-requeueable deps ti=<TaskInstance: api_to_db_dag.get_station_information manual__2025-02-28T14:13:40.619450+00:00 [queued]>
[2025-02-28T14:13:45.825+0000] {taskinstance.py:1125} INFO - Dependencies all met for dep_context=requeueable deps ti=<TaskInstance: api_to_db_dag.get_station_information manual__2025-02-28T14:13:40.619450+00:00 [queued]>
[2025-02-28T14:13:45.826+0000] {taskinstance.py:1331} INFO - Starting attempt 1 of 1
[2025-02-28T14:13:45.843+0000] {taskinstance.py:1350} INFO - Executing <Task(SimpleHttpOperator): get_station_information> on 2025-02-28 14:13:40.619450+00:00
[2025-02-28T14:13:45.851+0000] {clientserver.py:543} INFO - Closing down clientserver connection
[2025-02-28T14:13:45.851+0000] {standard_task_runner.py:57} INFO - Started process 1395 to run task
[2025-02-28T14:13:45.857+0000] {standard_task_runner.py:84} INFO - Running: ['***', 'tasks', 'run', 'api_to_db_dag', 'get_station_information', 'manual__2025-02-28T14:13:40.619450+00:00', '--job-id', '5', '--raw', '--subdir', 'DAGS_FOLDER/dag.py', '--cfg-path', '/tmp/tmpq0i8edp2']
[2025-02-28T14:13:45.859+0000] {standard_task_runner.py:85} INFO - Job 5: Subtask get_station_information
[2025-02-28T14:13:45.905+0000] {task_command.py:410} INFO - Running <TaskInstance: api_to_db_dag.get_station_information manual__2025-02-28T14:13:40.619450+00:00 [running]> on host 2e469bce1432
[2025-02-28T14:13:45.974+0000] {taskinstance.py:1570} INFO - Exporting env vars: AIRFLOW_CTX_DAG_OWNER='***' AIRFLOW_CTX_DAG_ID='api_to_db_dag' AIRFLOW_CTX_TASK_ID='get_station_information' AIRFLOW_CTX_EXECUTION_DATE='2025-02-28T14:13:40.619450+00:00' AIRFLOW_CTX_TRY_NUMBER='1' AIRFLOW_CTX_DAG_RUN_ID='manual__2025-02-28T14:13:40.619450+00:00'
[2025-02-28T14:13:45.975+0000] {http.py:123} INFO - Calling HTTP method
[2025-02-28T14:13:45.981+0000] {base.py:73} INFO - Using connection ID 'velib_api_connection' for task execution.
[2025-02-28T14:13:46.091+0000] {clientserver.py:505} INFO - Error while sending or receiving.
Traceback (most recent call last):
  File "/home/airflow/.local/lib/python3.7/site-packages/py4j/clientserver.py", line 503, in send_command
    self.socket.sendall(command.encode("utf-8"))
ConnectionResetError: [Errno 104] Connection reset by peer
[2025-02-28T14:13:46.093+0000] {clientserver.py:543} INFO - Closing down clientserver connection
[2025-02-28T14:13:46.094+0000] {java_gateway.py:1052} INFO - Exception while sending command.
Traceback (most recent call last):
  File "/home/airflow/.local/lib/python3.7/site-packages/py4j/clientserver.py", line 503, in send_command
    self.socket.sendall(command.encode("utf-8"))
ConnectionResetError: [Errno 104] Connection reset by peer

During handling of the above exception, another exception occurred:

Traceback (most recent call last):
  File "/home/airflow/.local/lib/python3.7/site-packages/py4j/java_gateway.py", line 1038, in send_command
    response = connection.send_command(command)
  File "/home/airflow/.local/lib/python3.7/site-packages/py4j/clientserver.py", line 507, in send_command
    "Error while sending", e, proto.ERROR_ON_SEND)
py4j.protocol.Py4JNetworkError: Error while sending
[2025-02-28T14:13:46.096+0000] {clientserver.py:543} INFO - Closing down clientserver connection
[2025-02-28T14:13:46.146+0000] {taskinstance.py:1373} INFO - Marking task as SUCCESS. dag_id=api_to_db_dag, task_id=get_station_information, execution_date=20250228T141340, start_date=20250228T141345, end_date=20250228T141346
[2025-02-28T14:13:46.159+0000] {local_task_job_runner.py:232} INFO - Task exited with return code 0
[2025-02-28T14:13:46.225+0000] {taskinstance.py:2674} INFO - 1 downstream tasks scheduled from follow-on schedule check
