[2025-03-02T18:59:46.713+0000] {taskinstance.py:1125} INFO - Dependencies all met for dep_context=non-requeueable deps ti=<TaskInstance: api_to_db_dag.process_raw_velib_station manual__2025-03-02T18:54:40.633475+00:00 [queued]>
[2025-03-02T18:59:46.720+0000] {taskinstance.py:1125} INFO - Dependencies all met for dep_context=requeueable deps ti=<TaskInstance: api_to_db_dag.process_raw_velib_station manual__2025-03-02T18:54:40.633475+00:00 [queued]>
[2025-03-02T18:59:46.720+0000] {taskinstance.py:1331} INFO - Starting attempt 2 of 2
[2025-03-02T18:59:46.733+0000] {taskinstance.py:1350} INFO - Executing <Task(PythonOperator): process_raw_velib_station> on 2025-03-02 18:54:40.633475+00:00
[2025-03-02T18:59:46.739+0000] {standard_task_runner.py:57} INFO - Started process 15396 to run task
[2025-03-02T18:59:46.744+0000] {standard_task_runner.py:84} INFO - Running: ['***', 'tasks', 'run', 'api_to_db_dag', 'process_raw_velib_station', 'manual__2025-03-02T18:54:40.633475+00:00', '--job-id', '145', '--raw', '--subdir', 'DAGS_FOLDER/dag.py', '--cfg-path', '/tmp/tmpzlmijfxf']
[2025-03-02T18:59:46.746+0000] {standard_task_runner.py:85} INFO - Job 145: Subtask process_raw_velib_station
[2025-03-02T18:59:46.798+0000] {task_command.py:410} INFO - Running <TaskInstance: api_to_db_dag.process_raw_velib_station manual__2025-03-02T18:54:40.633475+00:00 [running]> on host 3befbd719c1b
[2025-03-02T18:59:46.896+0000] {taskinstance.py:1570} INFO - Exporting env vars: AIRFLOW_CTX_DAG_OWNER='***' AIRFLOW_CTX_DAG_ID='api_to_db_dag' AIRFLOW_CTX_TASK_ID='process_raw_velib_station' AIRFLOW_CTX_EXECUTION_DATE='2025-03-02T18:54:40.633475+00:00' AIRFLOW_CTX_TRY_NUMBER='2' AIRFLOW_CTX_DAG_RUN_ID='manual__2025-03-02T18:54:40.633475+00:00'
[2025-03-02T18:59:46.900+0000] {taskinstance.py:1847} ERROR - Task failed with exception
Traceback (most recent call last):
  File "/home/airflow/.local/lib/python3.7/site-packages/airflow/operators/python.py", line 181, in execute
    return_value = self.execute_callable()
  File "/home/airflow/.local/lib/python3.7/site-packages/airflow/operators/python.py", line 198, in execute_callable
    return self.python_callable(*self.op_args, **self.op_kwargs)
  File "/opt/airflow/lib/utils.py", line 23, in process_files_in_directory
    function(full_path)
TypeError: format_velib_data() missing 1 required positional argument: 'input_path'
[2025-03-02T18:59:46.907+0000] {taskinstance.py:1373} INFO - Marking task as FAILED. dag_id=api_to_db_dag, task_id=process_raw_velib_station, execution_date=20250302T185440, start_date=20250302T185946, end_date=20250302T185946
[2025-03-02T18:59:46.915+0000] {standard_task_runner.py:109} ERROR - Failed to execute job 145 for task process_raw_velib_station (format_velib_data() missing 1 required positional argument: 'input_path'; 15396)
[2025-03-02T18:59:46.923+0000] {local_task_job_runner.py:232} INFO - Task exited with return code 1
[2025-03-02T18:59:46.948+0000] {taskinstance.py:2674} INFO - 0 downstream tasks scheduled from follow-on schedule check
