[2025-02-28T12:31:34.514+0000] {taskinstance.py:1125} INFO - Dependencies all met for dep_context=non-requeueable deps ti=<TaskInstance: api_to_db_dag.get_velib_data manual__2025-02-28T12:31:26.207595+00:00 [queued]>
[2025-02-28T12:31:34.526+0000] {taskinstance.py:1125} INFO - Dependencies all met for dep_context=requeueable deps ti=<TaskInstance: api_to_db_dag.get_velib_data manual__2025-02-28T12:31:26.207595+00:00 [queued]>
[2025-02-28T12:31:34.526+0000] {taskinstance.py:1331} INFO - Starting attempt 1 of 1
[2025-02-28T12:31:34.563+0000] {taskinstance.py:1350} INFO - Executing <Task(SimpleHttpOperator): get_velib_data> on 2025-02-28 12:31:26.207595+00:00
[2025-02-28T12:31:34.568+0000] {standard_task_runner.py:57} INFO - Started process 3605 to run task
[2025-02-28T12:31:34.569+0000] {clientserver.py:543} INFO - Closing down clientserver connection
[2025-02-28T12:31:34.577+0000] {standard_task_runner.py:84} INFO - Running: ['***', 'tasks', 'run', 'api_to_db_dag', 'get_velib_data', 'manual__2025-02-28T12:31:26.207595+00:00', '--job-id', '7', '--raw', '--subdir', 'DAGS_FOLDER/dag.py', '--cfg-path', '/tmp/tmpwymwlxob']
[2025-02-28T12:31:34.579+0000] {standard_task_runner.py:85} INFO - Job 7: Subtask get_velib_data
[2025-02-28T12:31:34.660+0000] {task_command.py:410} INFO - Running <TaskInstance: api_to_db_dag.get_velib_data manual__2025-02-28T12:31:26.207595+00:00 [running]> on host a0901dbddc07
[2025-02-28T12:31:34.739+0000] {taskinstance.py:1570} INFO - Exporting env vars: AIRFLOW_CTX_DAG_OWNER='***' AIRFLOW_CTX_DAG_ID='api_to_db_dag' AIRFLOW_CTX_TASK_ID='get_velib_data' AIRFLOW_CTX_EXECUTION_DATE='2025-02-28T12:31:26.207595+00:00' AIRFLOW_CTX_TRY_NUMBER='1' AIRFLOW_CTX_DAG_RUN_ID='manual__2025-02-28T12:31:26.207595+00:00'
[2025-02-28T12:31:34.751+0000] {http.py:123} INFO - Calling HTTP method
[2025-02-28T12:31:34.770+0000] {base.py:73} INFO - Using connection ID 'velib_api_connection' for task execution.
[2025-02-28T12:31:34.912+0000] {clientserver.py:505} INFO - Error while sending or receiving.
Traceback (most recent call last):
  File "/home/airflow/.local/lib/python3.7/site-packages/py4j/clientserver.py", line 503, in send_command
    self.socket.sendall(command.encode("utf-8"))
ConnectionResetError: [Errno 104] Connection reset by peer
[2025-02-28T12:31:34.919+0000] {clientserver.py:543} INFO - Closing down clientserver connection
[2025-02-28T12:31:34.921+0000] {java_gateway.py:1052} INFO - Exception while sending command.
Traceback (most recent call last):
  File "/home/airflow/.local/lib/python3.7/site-packages/py4j/clientserver.py", line 503, in send_command
    self.socket.sendall(command.encode("utf-8"))
ConnectionResetError: [Errno 104] Connection reset by peer

During handling of the above exception, another exception occurred:

Traceback (most recent call last):
  File "/home/airflow/.local/lib/python3.7/site-packages/py4j/java_gateway.py", line 1038, in send_command
    response = connection.send_command(command)
  File "/home/airflow/.local/lib/python3.7/site-packages/py4j/clientserver.py", line 507, in send_command
    "Error while sending", e, proto.ERROR_ON_SEND)
py4j.protocol.Py4JNetworkError: Error while sending
[2025-02-28T12:31:34.931+0000] {clientserver.py:543} INFO - Closing down clientserver connection
[2025-02-28T12:31:34.960+0000] {taskinstance.py:1373} INFO - Marking task as SUCCESS. dag_id=api_to_db_dag, task_id=get_velib_data, execution_date=20250228T123126, start_date=20250228T123134, end_date=20250228T123134
[2025-02-28T12:31:35.006+0000] {local_task_job_runner.py:232} INFO - Task exited with return code 0
[2025-02-28T12:31:35.049+0000] {taskinstance.py:2674} INFO - 1 downstream tasks scheduled from follow-on schedule check
