[2025-02-28T12:31:34.382+0000] {taskinstance.py:1125} INFO - Dependencies all met for dep_context=non-requeueable deps ti=<TaskInstance: api_to_db_dag.get_station_information scheduled__2025-02-27T00:00:00+00:00 [queued]>
[2025-02-28T12:31:34.396+0000] {taskinstance.py:1125} INFO - Dependencies all met for dep_context=requeueable deps ti=<TaskInstance: api_to_db_dag.get_station_information scheduled__2025-02-27T00:00:00+00:00 [queued]>
[2025-02-28T12:31:34.397+0000] {taskinstance.py:1331} INFO - Starting attempt 1 of 1
[2025-02-28T12:31:34.434+0000] {taskinstance.py:1350} INFO - Executing <Task(SimpleHttpOperator): get_station_information> on 2025-02-27 00:00:00+00:00
[2025-02-28T12:31:34.438+0000] {standard_task_runner.py:57} INFO - Started process 3585 to run task
[2025-02-28T12:31:34.439+0000] {clientserver.py:543} INFO - Closing down clientserver connection
[2025-02-28T12:31:34.444+0000] {standard_task_runner.py:84} INFO - Running: ['***', 'tasks', 'run', 'api_to_db_dag', 'get_station_information', 'scheduled__2025-02-27T00:00:00+00:00', '--job-id', '5', '--raw', '--subdir', 'DAGS_FOLDER/dag.py', '--cfg-path', '/tmp/tmpzygcgias']
[2025-02-28T12:31:34.447+0000] {standard_task_runner.py:85} INFO - Job 5: Subtask get_station_information
[2025-02-28T12:31:34.549+0000] {task_command.py:410} INFO - Running <TaskInstance: api_to_db_dag.get_station_information scheduled__2025-02-27T00:00:00+00:00 [running]> on host a0901dbddc07
[2025-02-28T12:31:34.703+0000] {taskinstance.py:1570} INFO - Exporting env vars: AIRFLOW_CTX_DAG_OWNER='***' AIRFLOW_CTX_DAG_ID='api_to_db_dag' AIRFLOW_CTX_TASK_ID='get_station_information' AIRFLOW_CTX_EXECUTION_DATE='2025-02-27T00:00:00+00:00' AIRFLOW_CTX_TRY_NUMBER='1' AIRFLOW_CTX_DAG_RUN_ID='scheduled__2025-02-27T00:00:00+00:00'
[2025-02-28T12:31:34.706+0000] {http.py:123} INFO - Calling HTTP method
[2025-02-28T12:31:34.714+0000] {base.py:73} INFO - Using connection ID 'velib_api_connection' for task execution.
[2025-02-28T12:31:34.841+0000] {clientserver.py:505} INFO - Error while sending or receiving.
Traceback (most recent call last):
  File "/home/airflow/.local/lib/python3.7/site-packages/py4j/clientserver.py", line 503, in send_command
    self.socket.sendall(command.encode("utf-8"))
ConnectionResetError: [Errno 104] Connection reset by peer
[2025-02-28T12:31:34.843+0000] {clientserver.py:543} INFO - Closing down clientserver connection
[2025-02-28T12:31:34.843+0000] {java_gateway.py:1052} INFO - Exception while sending command.
Traceback (most recent call last):
  File "/home/airflow/.local/lib/python3.7/site-packages/py4j/clientserver.py", line 503, in send_command
    self.socket.sendall(command.encode("utf-8"))
ConnectionResetError: [Errno 104] Connection reset by peer

During handling of the above exception, another exception occurred:

Traceback (most recent call last):
  File "/home/airflow/.local/lib/python3.7/site-packages/py4j/java_gateway.py", line 1038, in send_command
    response = connection.send_command(command)
  File "/home/airflow/.local/lib/python3.7/site-packages/py4j/clientserver.py", line 507, in send_command
    "Error while sending", e, proto.ERROR_ON_SEND)
py4j.protocol.Py4JNetworkError: Error while sending
[2025-02-28T12:31:34.847+0000] {clientserver.py:543} INFO - Closing down clientserver connection
[2025-02-28T12:31:34.929+0000] {taskinstance.py:1373} INFO - Marking task as SUCCESS. dag_id=api_to_db_dag, task_id=get_station_information, execution_date=20250227T000000, start_date=20250228T123134, end_date=20250228T123134
[2025-02-28T12:31:34.960+0000] {local_task_job_runner.py:232} INFO - Task exited with return code 0
[2025-02-28T12:31:34.987+0000] {taskinstance.py:2674} INFO - 1 downstream tasks scheduled from follow-on schedule check
[2025-02-28T12:38:24.300+0000] {taskinstance.py:1125} INFO - Dependencies all met for dep_context=non-requeueable deps ti=<TaskInstance: api_to_db_dag.get_station_information scheduled__2025-02-27T00:00:00+00:00 [queued]>
[2025-02-28T12:38:24.307+0000] {taskinstance.py:1125} INFO - Dependencies all met for dep_context=requeueable deps ti=<TaskInstance: api_to_db_dag.get_station_information scheduled__2025-02-27T00:00:00+00:00 [queued]>
[2025-02-28T12:38:24.308+0000] {taskinstance.py:1331} INFO - Starting attempt 1 of 1
[2025-02-28T12:38:24.318+0000] {taskinstance.py:1350} INFO - Executing <Task(SimpleHttpOperator): get_station_information> on 2025-02-27 00:00:00+00:00
[2025-02-28T12:38:24.325+0000] {standard_task_runner.py:57} INFO - Started process 928 to run task
[2025-02-28T12:38:24.325+0000] {clientserver.py:543} INFO - Closing down clientserver connection
[2025-02-28T12:38:24.339+0000] {standard_task_runner.py:84} INFO - Running: ['***', 'tasks', 'run', 'api_to_db_dag', 'get_station_information', 'scheduled__2025-02-27T00:00:00+00:00', '--job-id', '3', '--raw', '--subdir', 'DAGS_FOLDER/dag.py', '--cfg-path', '/tmp/tmpszoppo5e']
[2025-02-28T12:38:24.356+0000] {standard_task_runner.py:85} INFO - Job 3: Subtask get_station_information
[2025-02-28T12:38:24.427+0000] {task_command.py:410} INFO - Running <TaskInstance: api_to_db_dag.get_station_information scheduled__2025-02-27T00:00:00+00:00 [running]> on host 654b8dd452f4
[2025-02-28T12:38:24.493+0000] {clientserver.py:505} INFO - Error while sending or receiving.
Traceback (most recent call last):
  File "/home/airflow/.local/lib/python3.7/site-packages/py4j/clientserver.py", line 503, in send_command
    self.socket.sendall(command.encode("utf-8"))
ConnectionResetError: [Errno 104] Connection reset by peer
[2025-02-28T12:38:24.496+0000] {clientserver.py:543} INFO - Closing down clientserver connection
[2025-02-28T12:38:24.496+0000] {java_gateway.py:1052} INFO - Exception while sending command.
Traceback (most recent call last):
  File "/home/airflow/.local/lib/python3.7/site-packages/py4j/clientserver.py", line 503, in send_command
    self.socket.sendall(command.encode("utf-8"))
ConnectionResetError: [Errno 104] Connection reset by peer

During handling of the above exception, another exception occurred:

Traceback (most recent call last):
  File "/home/airflow/.local/lib/python3.7/site-packages/py4j/java_gateway.py", line 1038, in send_command
    response = connection.send_command(command)
  File "/home/airflow/.local/lib/python3.7/site-packages/py4j/clientserver.py", line 507, in send_command
    "Error while sending", e, proto.ERROR_ON_SEND)
py4j.protocol.Py4JNetworkError: Error while sending
[2025-02-28T12:38:24.500+0000] {clientserver.py:543} INFO - Closing down clientserver connection
[2025-02-28T12:38:24.519+0000] {taskinstance.py:1570} INFO - Exporting env vars: AIRFLOW_CTX_DAG_OWNER='***' AIRFLOW_CTX_DAG_ID='api_to_db_dag' AIRFLOW_CTX_TASK_ID='get_station_information' AIRFLOW_CTX_EXECUTION_DATE='2025-02-27T00:00:00+00:00' AIRFLOW_CTX_TRY_NUMBER='1' AIRFLOW_CTX_DAG_RUN_ID='scheduled__2025-02-27T00:00:00+00:00'
[2025-02-28T12:38:24.520+0000] {http.py:123} INFO - Calling HTTP method
[2025-02-28T12:38:24.526+0000] {base.py:73} INFO - Using connection ID 'velib_api_connection' for task execution.
[2025-02-28T12:38:24.744+0000] {taskinstance.py:1373} INFO - Marking task as SUCCESS. dag_id=api_to_db_dag, task_id=get_station_information, execution_date=20250227T000000, start_date=20250228T123824, end_date=20250228T123824
[2025-02-28T12:38:24.759+0000] {local_task_job_runner.py:232} INFO - Task exited with return code 0
[2025-02-28T12:38:24.780+0000] {taskinstance.py:2674} INFO - 1 downstream tasks scheduled from follow-on schedule check
[2025-02-28T13:00:39.958+0000] {taskinstance.py:1125} INFO - Dependencies all met for dep_context=non-requeueable deps ti=<TaskInstance: api_to_db_dag.get_station_information scheduled__2025-02-27T00:00:00+00:00 [queued]>
[2025-02-28T13:00:39.964+0000] {taskinstance.py:1125} INFO - Dependencies all met for dep_context=requeueable deps ti=<TaskInstance: api_to_db_dag.get_station_information scheduled__2025-02-27T00:00:00+00:00 [queued]>
[2025-02-28T13:00:39.964+0000] {taskinstance.py:1331} INFO - Starting attempt 1 of 1
[2025-02-28T13:00:39.974+0000] {taskinstance.py:1350} INFO - Executing <Task(SimpleHttpOperator): get_station_information> on 2025-02-27 00:00:00+00:00
[2025-02-28T13:00:39.980+0000] {clientserver.py:543} INFO - Closing down clientserver connection
[2025-02-28T13:00:39.979+0000] {standard_task_runner.py:57} INFO - Started process 1536 to run task
[2025-02-28T13:00:39.986+0000] {standard_task_runner.py:84} INFO - Running: ['***', 'tasks', 'run', 'api_to_db_dag', 'get_station_information', 'scheduled__2025-02-27T00:00:00+00:00', '--job-id', '2', '--raw', '--subdir', 'DAGS_FOLDER/dag.py', '--cfg-path', '/tmp/tmpn1765t9x']
[2025-02-28T13:00:39.988+0000] {standard_task_runner.py:85} INFO - Job 2: Subtask get_station_information
[2025-02-28T13:00:40.029+0000] {task_command.py:410} INFO - Running <TaskInstance: api_to_db_dag.get_station_information scheduled__2025-02-27T00:00:00+00:00 [running]> on host bedfa72ade93
[2025-02-28T13:00:40.144+0000] {taskinstance.py:1570} INFO - Exporting env vars: AIRFLOW_CTX_DAG_OWNER='***' AIRFLOW_CTX_DAG_ID='api_to_db_dag' AIRFLOW_CTX_TASK_ID='get_station_information' AIRFLOW_CTX_EXECUTION_DATE='2025-02-27T00:00:00+00:00' AIRFLOW_CTX_TRY_NUMBER='1' AIRFLOW_CTX_DAG_RUN_ID='scheduled__2025-02-27T00:00:00+00:00'
[2025-02-28T13:00:40.146+0000] {http.py:123} INFO - Calling HTTP method
[2025-02-28T13:00:40.154+0000] {base.py:73} INFO - Using connection ID 'velib_api_connection' for task execution.
[2025-02-28T13:00:40.254+0000] {clientserver.py:505} INFO - Error while sending or receiving.
Traceback (most recent call last):
  File "/home/airflow/.local/lib/python3.7/site-packages/py4j/clientserver.py", line 503, in send_command
    self.socket.sendall(command.encode("utf-8"))
ConnectionResetError: [Errno 104] Connection reset by peer
[2025-02-28T13:00:40.255+0000] {clientserver.py:543} INFO - Closing down clientserver connection
[2025-02-28T13:00:40.256+0000] {java_gateway.py:1052} INFO - Exception while sending command.
Traceback (most recent call last):
  File "/home/airflow/.local/lib/python3.7/site-packages/py4j/clientserver.py", line 503, in send_command
    self.socket.sendall(command.encode("utf-8"))
ConnectionResetError: [Errno 104] Connection reset by peer

During handling of the above exception, another exception occurred:

Traceback (most recent call last):
  File "/home/airflow/.local/lib/python3.7/site-packages/py4j/java_gateway.py", line 1038, in send_command
    response = connection.send_command(command)
  File "/home/airflow/.local/lib/python3.7/site-packages/py4j/clientserver.py", line 507, in send_command
    "Error while sending", e, proto.ERROR_ON_SEND)
py4j.protocol.Py4JNetworkError: Error while sending
[2025-02-28T13:00:40.257+0000] {clientserver.py:543} INFO - Closing down clientserver connection
[2025-02-28T13:00:40.360+0000] {taskinstance.py:1373} INFO - Marking task as SUCCESS. dag_id=api_to_db_dag, task_id=get_station_information, execution_date=20250227T000000, start_date=20250228T130039, end_date=20250228T130040
[2025-02-28T13:00:40.407+0000] {local_task_job_runner.py:232} INFO - Task exited with return code 0
[2025-02-28T13:00:40.427+0000] {taskinstance.py:2674} INFO - 1 downstream tasks scheduled from follow-on schedule check
[2025-02-28T13:24:05.214+0000] {taskinstance.py:1125} INFO - Dependencies all met for dep_context=non-requeueable deps ti=<TaskInstance: api_to_db_dag.get_station_information scheduled__2025-02-27T00:00:00+00:00 [queued]>
[2025-02-28T13:24:05.221+0000] {taskinstance.py:1125} INFO - Dependencies all met for dep_context=requeueable deps ti=<TaskInstance: api_to_db_dag.get_station_information scheduled__2025-02-27T00:00:00+00:00 [queued]>
[2025-02-28T13:24:05.222+0000] {taskinstance.py:1331} INFO - Starting attempt 1 of 1
[2025-02-28T13:24:05.232+0000] {taskinstance.py:1350} INFO - Executing <Task(SimpleHttpOperator): get_station_information> on 2025-02-27 00:00:00+00:00
[2025-02-28T13:24:05.235+0000] {standard_task_runner.py:57} INFO - Started process 930 to run task
[2025-02-28T13:24:05.235+0000] {clientserver.py:543} INFO - Closing down clientserver connection
[2025-02-28T13:24:05.241+0000] {standard_task_runner.py:84} INFO - Running: ['***', 'tasks', 'run', 'api_to_db_dag', 'get_station_information', 'scheduled__2025-02-27T00:00:00+00:00', '--job-id', '4', '--raw', '--subdir', 'DAGS_FOLDER/dag.py', '--cfg-path', '/tmp/tmpfp5wei_g']
[2025-02-28T13:24:05.244+0000] {standard_task_runner.py:85} INFO - Job 4: Subtask get_station_information
[2025-02-28T13:24:05.302+0000] {task_command.py:410} INFO - Running <TaskInstance: api_to_db_dag.get_station_information scheduled__2025-02-27T00:00:00+00:00 [running]> on host 1c784c6426d5
[2025-02-28T13:24:05.359+0000] {taskinstance.py:1570} INFO - Exporting env vars: AIRFLOW_CTX_DAG_OWNER='***' AIRFLOW_CTX_DAG_ID='api_to_db_dag' AIRFLOW_CTX_TASK_ID='get_station_information' AIRFLOW_CTX_EXECUTION_DATE='2025-02-27T00:00:00+00:00' AIRFLOW_CTX_TRY_NUMBER='1' AIRFLOW_CTX_DAG_RUN_ID='scheduled__2025-02-27T00:00:00+00:00'
[2025-02-28T13:24:05.360+0000] {http.py:123} INFO - Calling HTTP method
[2025-02-28T13:24:05.366+0000] {base.py:73} INFO - Using connection ID 'velib_api_connection' for task execution.
[2025-02-28T13:24:05.559+0000] {clientserver.py:505} INFO - Error while sending or receiving.
Traceback (most recent call last):
  File "/home/airflow/.local/lib/python3.7/site-packages/py4j/clientserver.py", line 503, in send_command
    self.socket.sendall(command.encode("utf-8"))
ConnectionResetError: [Errno 104] Connection reset by peer
[2025-02-28T13:24:05.562+0000] {clientserver.py:543} INFO - Closing down clientserver connection
[2025-02-28T13:24:05.564+0000] {java_gateway.py:1052} INFO - Exception while sending command.
Traceback (most recent call last):
  File "/home/airflow/.local/lib/python3.7/site-packages/py4j/clientserver.py", line 503, in send_command
    self.socket.sendall(command.encode("utf-8"))
ConnectionResetError: [Errno 104] Connection reset by peer

During handling of the above exception, another exception occurred:

Traceback (most recent call last):
  File "/home/airflow/.local/lib/python3.7/site-packages/py4j/java_gateway.py", line 1038, in send_command
    response = connection.send_command(command)
  File "/home/airflow/.local/lib/python3.7/site-packages/py4j/clientserver.py", line 507, in send_command
    "Error while sending", e, proto.ERROR_ON_SEND)
py4j.protocol.Py4JNetworkError: Error while sending
[2025-02-28T13:24:05.568+0000] {clientserver.py:543} INFO - Closing down clientserver connection
[2025-02-28T13:24:05.611+0000] {taskinstance.py:1373} INFO - Marking task as SUCCESS. dag_id=api_to_db_dag, task_id=get_station_information, execution_date=20250227T000000, start_date=20250228T132405, end_date=20250228T132405
[2025-02-28T13:24:05.626+0000] {local_task_job_runner.py:232} INFO - Task exited with return code 0
[2025-02-28T13:24:05.682+0000] {taskinstance.py:2674} INFO - 1 downstream tasks scheduled from follow-on schedule check
[2025-02-28T14:13:45.748+0000] {taskinstance.py:1125} INFO - Dependencies all met for dep_context=non-requeueable deps ti=<TaskInstance: api_to_db_dag.get_station_information scheduled__2025-02-27T00:00:00+00:00 [queued]>
[2025-02-28T14:13:45.762+0000] {taskinstance.py:1125} INFO - Dependencies all met for dep_context=requeueable deps ti=<TaskInstance: api_to_db_dag.get_station_information scheduled__2025-02-27T00:00:00+00:00 [queued]>
[2025-02-28T14:13:45.763+0000] {taskinstance.py:1331} INFO - Starting attempt 1 of 1
[2025-02-28T14:13:45.775+0000] {taskinstance.py:1350} INFO - Executing <Task(SimpleHttpOperator): get_station_information> on 2025-02-27 00:00:00+00:00
[2025-02-28T14:13:45.779+0000] {standard_task_runner.py:57} INFO - Started process 1393 to run task
[2025-02-28T14:13:45.779+0000] {clientserver.py:543} INFO - Closing down clientserver connection
[2025-02-28T14:13:45.783+0000] {standard_task_runner.py:84} INFO - Running: ['***', 'tasks', 'run', 'api_to_db_dag', 'get_station_information', 'scheduled__2025-02-27T00:00:00+00:00', '--job-id', '3', '--raw', '--subdir', 'DAGS_FOLDER/dag.py', '--cfg-path', '/tmp/tmpm9lr_37t']
[2025-02-28T14:13:45.785+0000] {standard_task_runner.py:85} INFO - Job 3: Subtask get_station_information
[2025-02-28T14:13:45.839+0000] {task_command.py:410} INFO - Running <TaskInstance: api_to_db_dag.get_station_information scheduled__2025-02-27T00:00:00+00:00 [running]> on host 2e469bce1432
[2025-02-28T14:13:45.900+0000] {taskinstance.py:1570} INFO - Exporting env vars: AIRFLOW_CTX_DAG_OWNER='***' AIRFLOW_CTX_DAG_ID='api_to_db_dag' AIRFLOW_CTX_TASK_ID='get_station_information' AIRFLOW_CTX_EXECUTION_DATE='2025-02-27T00:00:00+00:00' AIRFLOW_CTX_TRY_NUMBER='1' AIRFLOW_CTX_DAG_RUN_ID='scheduled__2025-02-27T00:00:00+00:00'
[2025-02-28T14:13:45.901+0000] {http.py:123} INFO - Calling HTTP method
[2025-02-28T14:13:45.907+0000] {base.py:73} INFO - Using connection ID 'velib_api_connection' for task execution.
[2025-02-28T14:13:46.096+0000] {taskinstance.py:1373} INFO - Marking task as SUCCESS. dag_id=api_to_db_dag, task_id=get_station_information, execution_date=20250227T000000, start_date=20250228T141345, end_date=20250228T141346
[2025-02-28T14:13:46.103+0000] {clientserver.py:505} INFO - Error while sending or receiving.
Traceback (most recent call last):
  File "/home/airflow/.local/lib/python3.7/site-packages/py4j/clientserver.py", line 503, in send_command
    self.socket.sendall(command.encode("utf-8"))
ConnectionResetError: [Errno 104] Connection reset by peer
[2025-02-28T14:13:46.105+0000] {clientserver.py:543} INFO - Closing down clientserver connection
[2025-02-28T14:13:46.109+0000] {java_gateway.py:1052} INFO - Exception while sending command.
Traceback (most recent call last):
  File "/home/airflow/.local/lib/python3.7/site-packages/py4j/clientserver.py", line 503, in send_command
    self.socket.sendall(command.encode("utf-8"))
ConnectionResetError: [Errno 104] Connection reset by peer

During handling of the above exception, another exception occurred:

Traceback (most recent call last):
  File "/home/airflow/.local/lib/python3.7/site-packages/py4j/java_gateway.py", line 1038, in send_command
    response = connection.send_command(command)
  File "/home/airflow/.local/lib/python3.7/site-packages/py4j/clientserver.py", line 507, in send_command
    "Error while sending", e, proto.ERROR_ON_SEND)
py4j.protocol.Py4JNetworkError: Error while sending
[2025-02-28T14:13:46.113+0000] {clientserver.py:543} INFO - Closing down clientserver connection
[2025-02-28T14:13:46.125+0000] {local_task_job_runner.py:232} INFO - Task exited with return code 0
[2025-02-28T14:13:46.154+0000] {taskinstance.py:2674} INFO - 0 downstream tasks scheduled from follow-on schedule check
