[2025-02-28T14:36:10.817+0000] {taskinstance.py:1125} INFO - Dependencies all met for dep_context=non-requeueable deps ti=<TaskInstance: api_to_db_dag.get_station_information manual__2025-02-28T14:36:06.056349+00:00 [queued]>
[2025-02-28T14:36:10.832+0000] {taskinstance.py:1125} INFO - Dependencies all met for dep_context=requeueable deps ti=<TaskInstance: api_to_db_dag.get_station_information manual__2025-02-28T14:36:06.056349+00:00 [queued]>
[2025-02-28T14:36:10.839+0000] {taskinstance.py:1331} INFO - Starting attempt 1 of 1
[2025-02-28T14:36:10.852+0000] {taskinstance.py:1350} INFO - Executing <Task(SimpleHttpOperator): get_station_information> on 2025-02-28 14:36:06.056349+00:00
[2025-02-28T14:36:10.859+0000] {standard_task_runner.py:57} INFO - Started process 10274 to run task
[2025-02-28T14:36:10.859+0000] {clientserver.py:543} INFO - Closing down clientserver connection
[2025-02-28T14:36:10.866+0000] {standard_task_runner.py:84} INFO - Running: ['***', 'tasks', 'run', 'api_to_db_dag', 'get_station_information', 'manual__2025-02-28T14:36:06.056349+00:00', '--job-id', '18', '--raw', '--subdir', 'DAGS_FOLDER/dag.py', '--cfg-path', '/tmp/tmp9yalktjw']
[2025-02-28T14:36:10.869+0000] {standard_task_runner.py:85} INFO - Job 18: Subtask get_station_information
[2025-02-28T14:36:10.925+0000] {clientserver.py:505} INFO - Error while sending or receiving.
Traceback (most recent call last):
  File "/home/airflow/.local/lib/python3.7/site-packages/py4j/clientserver.py", line 503, in send_command
    self.socket.sendall(command.encode("utf-8"))
ConnectionResetError: [Errno 104] Connection reset by peer
[2025-02-28T14:36:10.932+0000] {clientserver.py:543} INFO - Closing down clientserver connection
[2025-02-28T14:36:10.933+0000] {java_gateway.py:1052} INFO - Exception while sending command.
Traceback (most recent call last):
  File "/home/airflow/.local/lib/python3.7/site-packages/py4j/clientserver.py", line 503, in send_command
    self.socket.sendall(command.encode("utf-8"))
ConnectionResetError: [Errno 104] Connection reset by peer

During handling of the above exception, another exception occurred:

Traceback (most recent call last):
  File "/home/airflow/.local/lib/python3.7/site-packages/py4j/java_gateway.py", line 1038, in send_command
    response = connection.send_command(command)
  File "/home/airflow/.local/lib/python3.7/site-packages/py4j/clientserver.py", line 507, in send_command
    "Error while sending", e, proto.ERROR_ON_SEND)
py4j.protocol.Py4JNetworkError: Error while sending
[2025-02-28T14:36:10.941+0000] {clientserver.py:543} INFO - Closing down clientserver connection
[2025-02-28T14:36:10.946+0000] {task_command.py:410} INFO - Running <TaskInstance: api_to_db_dag.get_station_information manual__2025-02-28T14:36:06.056349+00:00 [running]> on host 2e469bce1432
[2025-02-28T14:36:11.028+0000] {taskinstance.py:1570} INFO - Exporting env vars: AIRFLOW_CTX_DAG_OWNER='***' AIRFLOW_CTX_DAG_ID='api_to_db_dag' AIRFLOW_CTX_TASK_ID='get_station_information' AIRFLOW_CTX_EXECUTION_DATE='2025-02-28T14:36:06.056349+00:00' AIRFLOW_CTX_TRY_NUMBER='1' AIRFLOW_CTX_DAG_RUN_ID='manual__2025-02-28T14:36:06.056349+00:00'
[2025-02-28T14:36:11.029+0000] {http.py:123} INFO - Calling HTTP method
[2025-02-28T14:36:11.035+0000] {base.py:73} INFO - Using connection ID 'velib_api_connection' for task execution.
[2025-02-28T14:36:11.188+0000] {taskinstance.py:1373} INFO - Marking task as SUCCESS. dag_id=api_to_db_dag, task_id=get_station_information, execution_date=20250228T143606, start_date=20250228T143610, end_date=20250228T143611
[2025-02-28T14:36:11.207+0000] {local_task_job_runner.py:232} INFO - Task exited with return code 0
[2025-02-28T14:36:11.233+0000] {taskinstance.py:2674} INFO - 1 downstream tasks scheduled from follow-on schedule check
