[2025-02-28T12:31:34.448+0000] {taskinstance.py:1125} INFO - Dependencies all met for dep_context=non-requeueable deps ti=<TaskInstance: api_to_db_dag.get_velib_data scheduled__2025-02-27T00:00:00+00:00 [queued]>
[2025-02-28T12:31:34.456+0000] {taskinstance.py:1125} INFO - Dependencies all met for dep_context=requeueable deps ti=<TaskInstance: api_to_db_dag.get_velib_data scheduled__2025-02-27T00:00:00+00:00 [queued]>
[2025-02-28T12:31:34.456+0000] {taskinstance.py:1331} INFO - Starting attempt 1 of 1
[2025-02-28T12:31:34.507+0000] {taskinstance.py:1350} INFO - Executing <Task(SimpleHttpOperator): get_velib_data> on 2025-02-27 00:00:00+00:00
[2025-02-28T12:31:34.512+0000] {standard_task_runner.py:57} INFO - Started process 3595 to run task
[2025-02-28T12:31:34.513+0000] {clientserver.py:543} INFO - Closing down clientserver connection
[2025-02-28T12:31:34.523+0000] {standard_task_runner.py:84} INFO - Running: ['***', 'tasks', 'run', 'api_to_db_dag', 'get_velib_data', 'scheduled__2025-02-27T00:00:00+00:00', '--job-id', '6', '--raw', '--subdir', 'DAGS_FOLDER/dag.py', '--cfg-path', '/tmp/tmpg2mb59fc']
[2025-02-28T12:31:34.526+0000] {standard_task_runner.py:85} INFO - Job 6: Subtask get_velib_data
[2025-02-28T12:31:34.624+0000] {task_command.py:410} INFO - Running <TaskInstance: api_to_db_dag.get_velib_data scheduled__2025-02-27T00:00:00+00:00 [running]> on host a0901dbddc07
[2025-02-28T12:31:34.724+0000] {taskinstance.py:1570} INFO - Exporting env vars: AIRFLOW_CTX_DAG_OWNER='***' AIRFLOW_CTX_DAG_ID='api_to_db_dag' AIRFLOW_CTX_TASK_ID='get_velib_data' AIRFLOW_CTX_EXECUTION_DATE='2025-02-27T00:00:00+00:00' AIRFLOW_CTX_TRY_NUMBER='1' AIRFLOW_CTX_DAG_RUN_ID='scheduled__2025-02-27T00:00:00+00:00'
[2025-02-28T12:31:34.727+0000] {http.py:123} INFO - Calling HTTP method
[2025-02-28T12:31:34.739+0000] {base.py:73} INFO - Using connection ID 'velib_api_connection' for task execution.
[2025-02-28T12:31:34.940+0000] {clientserver.py:505} INFO - Error while sending or receiving.
Traceback (most recent call last):
  File "/home/airflow/.local/lib/python3.7/site-packages/py4j/clientserver.py", line 503, in send_command
    self.socket.sendall(command.encode("utf-8"))
ConnectionResetError: [Errno 104] Connection reset by peer
[2025-02-28T12:31:34.942+0000] {clientserver.py:543} INFO - Closing down clientserver connection
[2025-02-28T12:31:34.944+0000] {java_gateway.py:1052} INFO - Exception while sending command.
Traceback (most recent call last):
  File "/home/airflow/.local/lib/python3.7/site-packages/py4j/clientserver.py", line 503, in send_command
    self.socket.sendall(command.encode("utf-8"))
ConnectionResetError: [Errno 104] Connection reset by peer

During handling of the above exception, another exception occurred:

Traceback (most recent call last):
  File "/home/airflow/.local/lib/python3.7/site-packages/py4j/java_gateway.py", line 1038, in send_command
    response = connection.send_command(command)
  File "/home/airflow/.local/lib/python3.7/site-packages/py4j/clientserver.py", line 507, in send_command
    "Error while sending", e, proto.ERROR_ON_SEND)
py4j.protocol.Py4JNetworkError: Error while sending
[2025-02-28T12:31:34.948+0000] {clientserver.py:543} INFO - Closing down clientserver connection
[2025-02-28T12:31:34.960+0000] {taskinstance.py:1373} INFO - Marking task as SUCCESS. dag_id=api_to_db_dag, task_id=get_velib_data, execution_date=20250227T000000, start_date=20250228T123134, end_date=20250228T123134
[2025-02-28T12:31:34.988+0000] {local_task_job_runner.py:232} INFO - Task exited with return code 0
[2025-02-28T12:31:35.032+0000] {taskinstance.py:2674} INFO - 1 downstream tasks scheduled from follow-on schedule check
[2025-02-28T12:38:24.308+0000] {taskinstance.py:1125} INFO - Dependencies all met for dep_context=non-requeueable deps ti=<TaskInstance: api_to_db_dag.get_velib_data scheduled__2025-02-27T00:00:00+00:00 [queued]>
[2025-02-28T12:38:24.315+0000] {taskinstance.py:1125} INFO - Dependencies all met for dep_context=requeueable deps ti=<TaskInstance: api_to_db_dag.get_velib_data scheduled__2025-02-27T00:00:00+00:00 [queued]>
[2025-02-28T12:38:24.318+0000] {taskinstance.py:1331} INFO - Starting attempt 1 of 1
[2025-02-28T12:38:24.333+0000] {taskinstance.py:1350} INFO - Executing <Task(SimpleHttpOperator): get_velib_data> on 2025-02-27 00:00:00+00:00
[2025-02-28T12:38:24.337+0000] {clientserver.py:543} INFO - Closing down clientserver connection
[2025-02-28T12:38:24.337+0000] {standard_task_runner.py:57} INFO - Started process 930 to run task
[2025-02-28T12:38:24.361+0000] {standard_task_runner.py:84} INFO - Running: ['***', 'tasks', 'run', 'api_to_db_dag', 'get_velib_data', 'scheduled__2025-02-27T00:00:00+00:00', '--job-id', '4', '--raw', '--subdir', 'DAGS_FOLDER/dag.py', '--cfg-path', '/tmp/tmp5m15c6hs']
[2025-02-28T12:38:24.363+0000] {standard_task_runner.py:85} INFO - Job 4: Subtask get_velib_data
[2025-02-28T12:38:24.427+0000] {task_command.py:410} INFO - Running <TaskInstance: api_to_db_dag.get_velib_data scheduled__2025-02-27T00:00:00+00:00 [running]> on host 654b8dd452f4
[2025-02-28T12:38:24.498+0000] {clientserver.py:505} INFO - Error while sending or receiving.
Traceback (most recent call last):
  File "/home/airflow/.local/lib/python3.7/site-packages/py4j/clientserver.py", line 503, in send_command
    self.socket.sendall(command.encode("utf-8"))
ConnectionResetError: [Errno 104] Connection reset by peer
[2025-02-28T12:38:24.503+0000] {clientserver.py:543} INFO - Closing down clientserver connection
[2025-02-28T12:38:24.507+0000] {java_gateway.py:1052} INFO - Exception while sending command.
Traceback (most recent call last):
  File "/home/airflow/.local/lib/python3.7/site-packages/py4j/clientserver.py", line 503, in send_command
    self.socket.sendall(command.encode("utf-8"))
ConnectionResetError: [Errno 104] Connection reset by peer

During handling of the above exception, another exception occurred:

Traceback (most recent call last):
  File "/home/airflow/.local/lib/python3.7/site-packages/py4j/java_gateway.py", line 1038, in send_command
    response = connection.send_command(command)
  File "/home/airflow/.local/lib/python3.7/site-packages/py4j/clientserver.py", line 507, in send_command
    "Error while sending", e, proto.ERROR_ON_SEND)
py4j.protocol.Py4JNetworkError: Error while sending
[2025-02-28T12:38:24.510+0000] {clientserver.py:543} INFO - Closing down clientserver connection
[2025-02-28T12:38:24.516+0000] {taskinstance.py:1570} INFO - Exporting env vars: AIRFLOW_CTX_DAG_OWNER='***' AIRFLOW_CTX_DAG_ID='api_to_db_dag' AIRFLOW_CTX_TASK_ID='get_velib_data' AIRFLOW_CTX_EXECUTION_DATE='2025-02-27T00:00:00+00:00' AIRFLOW_CTX_TRY_NUMBER='1' AIRFLOW_CTX_DAG_RUN_ID='scheduled__2025-02-27T00:00:00+00:00'
[2025-02-28T12:38:24.517+0000] {http.py:123} INFO - Calling HTTP method
[2025-02-28T12:38:24.523+0000] {base.py:73} INFO - Using connection ID 'velib_api_connection' for task execution.
[2025-02-28T12:38:24.723+0000] {taskinstance.py:1373} INFO - Marking task as SUCCESS. dag_id=api_to_db_dag, task_id=get_velib_data, execution_date=20250227T000000, start_date=20250228T123824, end_date=20250228T123824
[2025-02-28T12:38:24.768+0000] {local_task_job_runner.py:232} INFO - Task exited with return code 0
[2025-02-28T12:38:24.797+0000] {taskinstance.py:2674} INFO - 1 downstream tasks scheduled from follow-on schedule check
[2025-02-28T13:00:40.203+0000] {taskinstance.py:1125} INFO - Dependencies all met for dep_context=non-requeueable deps ti=<TaskInstance: api_to_db_dag.get_velib_data scheduled__2025-02-27T00:00:00+00:00 [queued]>
[2025-02-28T13:00:40.209+0000] {taskinstance.py:1125} INFO - Dependencies all met for dep_context=requeueable deps ti=<TaskInstance: api_to_db_dag.get_velib_data scheduled__2025-02-27T00:00:00+00:00 [queued]>
[2025-02-28T13:00:40.210+0000] {taskinstance.py:1331} INFO - Starting attempt 1 of 1
[2025-02-28T13:00:40.219+0000] {taskinstance.py:1350} INFO - Executing <Task(SimpleHttpOperator): get_velib_data> on 2025-02-27 00:00:00+00:00
[2025-02-28T13:00:40.223+0000] {standard_task_runner.py:57} INFO - Started process 1538 to run task
[2025-02-28T13:00:40.223+0000] {clientserver.py:543} INFO - Closing down clientserver connection
[2025-02-28T13:00:40.227+0000] {standard_task_runner.py:84} INFO - Running: ['***', 'tasks', 'run', 'api_to_db_dag', 'get_velib_data', 'scheduled__2025-02-27T00:00:00+00:00', '--job-id', '5', '--raw', '--subdir', 'DAGS_FOLDER/dag.py', '--cfg-path', '/tmp/tmpp1typm6v']
[2025-02-28T13:00:40.228+0000] {standard_task_runner.py:85} INFO - Job 5: Subtask get_velib_data
[2025-02-28T13:00:40.265+0000] {task_command.py:410} INFO - Running <TaskInstance: api_to_db_dag.get_velib_data scheduled__2025-02-27T00:00:00+00:00 [running]> on host bedfa72ade93
[2025-02-28T13:00:40.329+0000] {taskinstance.py:1570} INFO - Exporting env vars: AIRFLOW_CTX_DAG_OWNER='***' AIRFLOW_CTX_DAG_ID='api_to_db_dag' AIRFLOW_CTX_TASK_ID='get_velib_data' AIRFLOW_CTX_EXECUTION_DATE='2025-02-27T00:00:00+00:00' AIRFLOW_CTX_TRY_NUMBER='1' AIRFLOW_CTX_DAG_RUN_ID='scheduled__2025-02-27T00:00:00+00:00'
[2025-02-28T13:00:40.330+0000] {http.py:123} INFO - Calling HTTP method
[2025-02-28T13:00:40.335+0000] {base.py:73} INFO - Using connection ID 'velib_api_connection' for task execution.
[2025-02-28T13:00:40.351+0000] {clientserver.py:505} INFO - Error while sending or receiving.
Traceback (most recent call last):
  File "/home/airflow/.local/lib/python3.7/site-packages/py4j/clientserver.py", line 503, in send_command
    self.socket.sendall(command.encode("utf-8"))
ConnectionResetError: [Errno 104] Connection reset by peer
[2025-02-28T13:00:40.352+0000] {clientserver.py:543} INFO - Closing down clientserver connection
[2025-02-28T13:00:40.352+0000] {java_gateway.py:1052} INFO - Exception while sending command.
Traceback (most recent call last):
  File "/home/airflow/.local/lib/python3.7/site-packages/py4j/clientserver.py", line 503, in send_command
    self.socket.sendall(command.encode("utf-8"))
ConnectionResetError: [Errno 104] Connection reset by peer

During handling of the above exception, another exception occurred:

Traceback (most recent call last):
  File "/home/airflow/.local/lib/python3.7/site-packages/py4j/java_gateway.py", line 1038, in send_command
    response = connection.send_command(command)
  File "/home/airflow/.local/lib/python3.7/site-packages/py4j/clientserver.py", line 507, in send_command
    "Error while sending", e, proto.ERROR_ON_SEND)
py4j.protocol.Py4JNetworkError: Error while sending
[2025-02-28T13:00:40.355+0000] {clientserver.py:543} INFO - Closing down clientserver connection
[2025-02-28T13:00:40.545+0000] {taskinstance.py:1373} INFO - Marking task as SUCCESS. dag_id=api_to_db_dag, task_id=get_velib_data, execution_date=20250227T000000, start_date=20250228T130040, end_date=20250228T130040
[2025-02-28T13:00:40.567+0000] {local_task_job_runner.py:232} INFO - Task exited with return code 0
[2025-02-28T13:00:40.589+0000] {taskinstance.py:2674} INFO - 1 downstream tasks scheduled from follow-on schedule check
[2025-02-28T13:24:05.157+0000] {taskinstance.py:1125} INFO - Dependencies all met for dep_context=non-requeueable deps ti=<TaskInstance: api_to_db_dag.get_velib_data scheduled__2025-02-27T00:00:00+00:00 [queued]>
[2025-02-28T13:24:05.167+0000] {taskinstance.py:1125} INFO - Dependencies all met for dep_context=requeueable deps ti=<TaskInstance: api_to_db_dag.get_velib_data scheduled__2025-02-27T00:00:00+00:00 [queued]>
[2025-02-28T13:24:05.170+0000] {taskinstance.py:1331} INFO - Starting attempt 1 of 1
[2025-02-28T13:24:05.184+0000] {taskinstance.py:1350} INFO - Executing <Task(SimpleHttpOperator): get_velib_data> on 2025-02-27 00:00:00+00:00
[2025-02-28T13:24:05.188+0000] {clientserver.py:543} INFO - Closing down clientserver connection
[2025-02-28T13:24:05.188+0000] {standard_task_runner.py:57} INFO - Started process 929 to run task
[2025-02-28T13:24:05.195+0000] {standard_task_runner.py:84} INFO - Running: ['***', 'tasks', 'run', 'api_to_db_dag', 'get_velib_data', 'scheduled__2025-02-27T00:00:00+00:00', '--job-id', '3', '--raw', '--subdir', 'DAGS_FOLDER/dag.py', '--cfg-path', '/tmp/tmpt1t82i4m']
[2025-02-28T13:24:05.197+0000] {standard_task_runner.py:85} INFO - Job 3: Subtask get_velib_data
[2025-02-28T13:24:05.240+0000] {task_command.py:410} INFO - Running <TaskInstance: api_to_db_dag.get_velib_data scheduled__2025-02-27T00:00:00+00:00 [running]> on host 1c784c6426d5
[2025-02-28T13:24:05.320+0000] {taskinstance.py:1570} INFO - Exporting env vars: AIRFLOW_CTX_DAG_OWNER='***' AIRFLOW_CTX_DAG_ID='api_to_db_dag' AIRFLOW_CTX_TASK_ID='get_velib_data' AIRFLOW_CTX_EXECUTION_DATE='2025-02-27T00:00:00+00:00' AIRFLOW_CTX_TRY_NUMBER='1' AIRFLOW_CTX_DAG_RUN_ID='scheduled__2025-02-27T00:00:00+00:00'
[2025-02-28T13:24:05.321+0000] {http.py:123} INFO - Calling HTTP method
[2025-02-28T13:24:05.328+0000] {base.py:73} INFO - Using connection ID 'velib_api_connection' for task execution.
[2025-02-28T13:24:05.557+0000] {taskinstance.py:1373} INFO - Marking task as SUCCESS. dag_id=api_to_db_dag, task_id=get_velib_data, execution_date=20250227T000000, start_date=20250228T132405, end_date=20250228T132405
[2025-02-28T13:24:05.557+0000] {clientserver.py:505} INFO - Error while sending or receiving.
Traceback (most recent call last):
  File "/home/airflow/.local/lib/python3.7/site-packages/py4j/clientserver.py", line 503, in send_command
    self.socket.sendall(command.encode("utf-8"))
ConnectionResetError: [Errno 104] Connection reset by peer
[2025-02-28T13:24:05.561+0000] {clientserver.py:543} INFO - Closing down clientserver connection
[2025-02-28T13:24:05.561+0000] {java_gateway.py:1052} INFO - Exception while sending command.
Traceback (most recent call last):
  File "/home/airflow/.local/lib/python3.7/site-packages/py4j/clientserver.py", line 503, in send_command
    self.socket.sendall(command.encode("utf-8"))
ConnectionResetError: [Errno 104] Connection reset by peer

During handling of the above exception, another exception occurred:

Traceback (most recent call last):
  File "/home/airflow/.local/lib/python3.7/site-packages/py4j/java_gateway.py", line 1038, in send_command
    response = connection.send_command(command)
  File "/home/airflow/.local/lib/python3.7/site-packages/py4j/clientserver.py", line 507, in send_command
    "Error while sending", e, proto.ERROR_ON_SEND)
py4j.protocol.Py4JNetworkError: Error while sending
[2025-02-28T13:24:05.569+0000] {clientserver.py:543} INFO - Closing down clientserver connection
[2025-02-28T13:24:05.619+0000] {local_task_job_runner.py:232} INFO - Task exited with return code 0
[2025-02-28T13:24:05.648+0000] {taskinstance.py:2674} INFO - 1 downstream tasks scheduled from follow-on schedule check
[2025-02-28T14:13:45.711+0000] {taskinstance.py:1125} INFO - Dependencies all met for dep_context=non-requeueable deps ti=<TaskInstance: api_to_db_dag.get_velib_data scheduled__2025-02-27T00:00:00+00:00 [queued]>
[2025-02-28T14:13:45.717+0000] {taskinstance.py:1125} INFO - Dependencies all met for dep_context=requeueable deps ti=<TaskInstance: api_to_db_dag.get_velib_data scheduled__2025-02-27T00:00:00+00:00 [queued]>
[2025-02-28T14:13:45.718+0000] {taskinstance.py:1331} INFO - Starting attempt 1 of 1
[2025-02-28T14:13:45.728+0000] {taskinstance.py:1350} INFO - Executing <Task(SimpleHttpOperator): get_velib_data> on 2025-02-27 00:00:00+00:00
[2025-02-28T14:13:45.733+0000] {clientserver.py:543} INFO - Closing down clientserver connection
[2025-02-28T14:13:45.733+0000] {standard_task_runner.py:57} INFO - Started process 1392 to run task
[2025-02-28T14:13:45.738+0000] {standard_task_runner.py:84} INFO - Running: ['***', 'tasks', 'run', 'api_to_db_dag', 'get_velib_data', 'scheduled__2025-02-27T00:00:00+00:00', '--job-id', '2', '--raw', '--subdir', 'DAGS_FOLDER/dag.py', '--cfg-path', '/tmp/tmpo40nt7v4']
[2025-02-28T14:13:45.740+0000] {standard_task_runner.py:85} INFO - Job 2: Subtask get_velib_data
[2025-02-28T14:13:45.796+0000] {task_command.py:410} INFO - Running <TaskInstance: api_to_db_dag.get_velib_data scheduled__2025-02-27T00:00:00+00:00 [running]> on host 2e469bce1432
[2025-02-28T14:13:45.882+0000] {taskinstance.py:1570} INFO - Exporting env vars: AIRFLOW_CTX_DAG_OWNER='***' AIRFLOW_CTX_DAG_ID='api_to_db_dag' AIRFLOW_CTX_TASK_ID='get_velib_data' AIRFLOW_CTX_EXECUTION_DATE='2025-02-27T00:00:00+00:00' AIRFLOW_CTX_TRY_NUMBER='1' AIRFLOW_CTX_DAG_RUN_ID='scheduled__2025-02-27T00:00:00+00:00'
[2025-02-28T14:13:45.885+0000] {http.py:123} INFO - Calling HTTP method
[2025-02-28T14:13:45.891+0000] {base.py:73} INFO - Using connection ID 'velib_api_connection' for task execution.
[2025-02-28T14:13:46.098+0000] {clientserver.py:505} INFO - Error while sending or receiving.
Traceback (most recent call last):
  File "/home/airflow/.local/lib/python3.7/site-packages/py4j/clientserver.py", line 503, in send_command
    self.socket.sendall(command.encode("utf-8"))
ConnectionResetError: [Errno 104] Connection reset by peer
[2025-02-28T14:13:46.100+0000] {clientserver.py:543} INFO - Closing down clientserver connection
[2025-02-28T14:13:46.100+0000] {java_gateway.py:1052} INFO - Exception while sending command.
Traceback (most recent call last):
  File "/home/airflow/.local/lib/python3.7/site-packages/py4j/clientserver.py", line 503, in send_command
    self.socket.sendall(command.encode("utf-8"))
ConnectionResetError: [Errno 104] Connection reset by peer

During handling of the above exception, another exception occurred:

Traceback (most recent call last):
  File "/home/airflow/.local/lib/python3.7/site-packages/py4j/java_gateway.py", line 1038, in send_command
    response = connection.send_command(command)
  File "/home/airflow/.local/lib/python3.7/site-packages/py4j/clientserver.py", line 507, in send_command
    "Error while sending", e, proto.ERROR_ON_SEND)
py4j.protocol.Py4JNetworkError: Error while sending
[2025-02-28T14:13:46.105+0000] {clientserver.py:543} INFO - Closing down clientserver connection
[2025-02-28T14:13:46.127+0000] {taskinstance.py:1373} INFO - Marking task as SUCCESS. dag_id=api_to_db_dag, task_id=get_velib_data, execution_date=20250227T000000, start_date=20250228T141345, end_date=20250228T141346
[2025-02-28T14:13:46.163+0000] {local_task_job_runner.py:232} INFO - Task exited with return code 0
[2025-02-28T14:13:46.232+0000] {taskinstance.py:2674} INFO - 1 downstream tasks scheduled from follow-on schedule check
