[2025-02-27T20:59:27.071+0000] {taskinstance.py:1125} INFO - Dependencies all met for dep_context=non-requeueable deps ti=<TaskInstance: api_to_db_dag.process_raw_station_information manual__2025-02-27T20:59:23.020207+00:00 [queued]>
[2025-02-27T20:59:27.076+0000] {taskinstance.py:1125} INFO - Dependencies all met for dep_context=requeueable deps ti=<TaskInstance: api_to_db_dag.process_raw_station_information manual__2025-02-27T20:59:23.020207+00:00 [queued]>
[2025-02-27T20:59:27.076+0000] {taskinstance.py:1331} INFO - Starting attempt 1 of 1
[2025-02-27T20:59:27.084+0000] {taskinstance.py:1350} INFO - Executing <Task(PythonOperator): process_raw_station_information> on 2025-02-27 20:59:23.020207+00:00
[2025-02-27T20:59:27.087+0000] {standard_task_runner.py:57} INFO - Started process 1206 to run task
[2025-02-27T20:59:27.090+0000] {standard_task_runner.py:84} INFO - Running: ['***', 'tasks', 'run', 'api_to_db_dag', 'process_raw_station_information', 'manual__2025-02-27T20:59:23.020207+00:00', '--job-id', '32', '--raw', '--subdir', 'DAGS_FOLDER/dag.py', '--cfg-path', '/tmp/tmpl1a7lzhq']
[2025-02-27T20:59:27.091+0000] {standard_task_runner.py:85} INFO - Job 32: Subtask process_raw_station_information
[2025-02-27T20:59:27.119+0000] {task_command.py:410} INFO - Running <TaskInstance: api_to_db_dag.process_raw_station_information manual__2025-02-27T20:59:23.020207+00:00 [running]> on host 53fdc8261bae
[2025-02-27T20:59:27.296+0000] {taskinstance.py:1570} INFO - Exporting env vars: AIRFLOW_CTX_DAG_OWNER='***' AIRFLOW_CTX_DAG_ID='api_to_db_dag' AIRFLOW_CTX_TASK_ID='process_raw_station_information' AIRFLOW_CTX_EXECUTION_DATE='2025-02-27T20:59:23.020207+00:00' AIRFLOW_CTX_TRY_NUMBER='1' AIRFLOW_CTX_DAG_RUN_ID='manual__2025-02-27T20:59:23.020207+00:00'
[2025-02-27T20:59:27.335+0000] {taskinstance.py:1847} ERROR - Task failed with exception
Traceback (most recent call last):
  File "/home/airflow/.local/lib/python3.7/site-packages/airflow/operators/python.py", line 181, in execute
    return_value = self.execute_callable()
  File "/home/airflow/.local/lib/python3.7/site-packages/airflow/operators/python.py", line 198, in execute_callable
    return self.python_callable(*self.op_args, **self.op_kwargs)
  File "/opt/airflow/dags/dag.py", line 24, in process_files_in_directory
    convert_and_save_to_formatted(full_path)
  File "/opt/airflow/dags/dag.py", line 54, in convert_and_save_to_formatted
    final_df.columns = df.columns.map(str)
  File "/home/airflow/.local/lib/python3.7/site-packages/pandas/core/generic.py", line 5500, in __setattr__
    return object.__setattr__(self, name, value)
  File "pandas/_libs/properties.pyx", line 70, in pandas._libs.properties.AxisProperty.__set__
  File "/home/airflow/.local/lib/python3.7/site-packages/pandas/core/generic.py", line 766, in _set_axis
    self._mgr.set_axis(axis, labels)
  File "/home/airflow/.local/lib/python3.7/site-packages/pandas/core/internals/managers.py", line 216, in set_axis
    self._validate_set_axis(axis, new_labels)
  File "/home/airflow/.local/lib/python3.7/site-packages/pandas/core/internals/base.py", line 58, in _validate_set_axis
    f"Length mismatch: Expected axis has {old_len} elements, new "
ValueError: Length mismatch: Expected axis has 1475 elements, new values have 3 elements
[2025-02-27T20:59:27.343+0000] {taskinstance.py:1373} INFO - Marking task as FAILED. dag_id=api_to_db_dag, task_id=process_raw_station_information, execution_date=20250227T205923, start_date=20250227T205927, end_date=20250227T205927
[2025-02-27T20:59:27.350+0000] {standard_task_runner.py:109} ERROR - Failed to execute job 32 for task process_raw_station_information (Length mismatch: Expected axis has 1475 elements, new values have 3 elements; 1206)
[2025-02-27T20:59:27.392+0000] {local_task_job_runner.py:232} INFO - Task exited with return code 1
[2025-02-27T20:59:27.411+0000] {taskinstance.py:2674} INFO - 0 downstream tasks scheduled from follow-on schedule check
