[2025-02-26T15:27:49.606+0000] {taskinstance.py:1087} INFO - Dependencies all met for <TaskInstance: api_to_db_dag.create_velib_station_status_table manual__2025-02-26T15:27:49.074260+00:00 [queued]>
[2025-02-26T15:27:49.613+0000] {taskinstance.py:1087} INFO - Dependencies all met for <TaskInstance: api_to_db_dag.create_velib_station_status_table manual__2025-02-26T15:27:49.074260+00:00 [queued]>
[2025-02-26T15:27:49.614+0000] {taskinstance.py:1283} INFO - 
--------------------------------------------------------------------------------
[2025-02-26T15:27:49.614+0000] {taskinstance.py:1284} INFO - Starting attempt 1 of 1
[2025-02-26T15:27:49.614+0000] {taskinstance.py:1285} INFO - 
--------------------------------------------------------------------------------
[2025-02-26T15:27:49.622+0000] {taskinstance.py:1304} INFO - Executing <Task(PostgresOperator): create_velib_station_status_table> on 2025-02-26 15:27:49.074260+00:00
[2025-02-26T15:27:49.624+0000] {standard_task_runner.py:55} INFO - Started process 182 to run task
[2025-02-26T15:27:49.626+0000] {standard_task_runner.py:82} INFO - Running: ['***', 'tasks', 'run', 'api_to_db_dag', 'create_velib_station_status_table', 'manual__2025-02-26T15:27:49.074260+00:00', '--job-id', '3', '--raw', '--subdir', 'DAGS_FOLDER/dag.py', '--cfg-path', '/tmp/tmpgehedsth']
[2025-02-26T15:27:49.627+0000] {standard_task_runner.py:83} INFO - Job 3: Subtask create_velib_station_status_table
[2025-02-26T15:27:49.662+0000] {task_command.py:389} INFO - Running <TaskInstance: api_to_db_dag.create_velib_station_status_table manual__2025-02-26T15:27:49.074260+00:00 [running]> on host 56549796aa94
[2025-02-26T15:27:49.700+0000] {taskinstance.py:1513} INFO - Exporting the following env vars:
AIRFLOW_CTX_DAG_OWNER=***
AIRFLOW_CTX_DAG_ID=api_to_db_dag
AIRFLOW_CTX_TASK_ID=create_velib_station_status_table
AIRFLOW_CTX_EXECUTION_DATE=2025-02-26T15:27:49.074260+00:00
AIRFLOW_CTX_TRY_NUMBER=1
AIRFLOW_CTX_DAG_RUN_ID=manual__2025-02-26T15:27:49.074260+00:00
[2025-02-26T15:27:49.700+0000] {sql.py:253} INFO - Executing: 
            CREATE TABLE IF NOT EXISTS velib_station_status (
                station_id INT,
                is_installed BOOLEAN,
                is_renting BOOLEAN,
                is_returning BOOLEAN,
                last_reported TIMESTAMP,
                numBikesAvailable INT,
                numDocksAvailable INT,
                num_bikes_available INT,
                num_ebikes_available INT,
                num_mechanical_bikes_available INT,
                num_docks_available INT
            );
            
[2025-02-26T15:27:49.707+0000] {base.py:73} INFO - Using connection ID 'postgres_default' for task execution.
[2025-02-26T15:27:49.799+0000] {base.py:73} INFO - Using connection ID 'postgres_default' for task execution.
[2025-02-26T15:27:49.801+0000] {taskinstance.py:1772} ERROR - Task failed with exception
Traceback (most recent call last):
  File "/home/airflow/.local/lib/python3.7/site-packages/airflow/providers/common/sql/operators/sql.py", line 261, in execute
    return_last=self.return_last,
  File "/home/airflow/.local/lib/python3.7/site-packages/airflow/providers/common/sql/hooks/sql.py", line 331, in run
    with closing(self.get_conn()) as conn:
  File "/home/airflow/.local/lib/python3.7/site-packages/airflow/providers/postgres/hooks/postgres.py", line 144, in get_conn
    self.conn = psycopg2.connect(**conn_args)
  File "/home/airflow/.local/lib/python3.7/site-packages/psycopg2/__init__.py", line 122, in connect
    conn = _connect(dsn, connection_factory=connection_factory, **kwasync)
psycopg2.OperationalError: connection to server at "postgres" (172.18.0.2), port 5432 failed: FATAL:  password authentication failed for user "postgres"

[2025-02-26T15:27:49.805+0000] {taskinstance.py:1327} INFO - Marking task as FAILED. dag_id=api_to_db_dag, task_id=create_velib_station_status_table, execution_date=20250226T152749, start_date=20250226T152749, end_date=20250226T152749
[2025-02-26T15:27:49.810+0000] {standard_task_runner.py:105} ERROR - Failed to execute job 3 for task create_velib_station_status_table (connection to server at "postgres" (172.18.0.2), port 5432 failed: FATAL:  password authentication failed for user "postgres"
; 182)
[2025-02-26T15:27:49.850+0000] {local_task_job.py:159} INFO - Task exited with return code 1
[2025-02-26T15:27:49.864+0000] {taskinstance.py:2582} INFO - 0 downstream tasks scheduled from follow-on schedule check
