[2025-03-02T19:06:57.423+0000] {taskinstance.py:1125} INFO - Dependencies all met for dep_context=non-requeueable deps ti=<TaskInstance: api_to_db_dag.save_raw_station_details_information manual__2025-03-02T19:06:07.855037+00:00 [queued]>
[2025-03-02T19:06:57.439+0000] {taskinstance.py:1125} INFO - Dependencies all met for dep_context=requeueable deps ti=<TaskInstance: api_to_db_dag.save_raw_station_details_information manual__2025-03-02T19:06:07.855037+00:00 [queued]>
[2025-03-02T19:06:57.442+0000] {taskinstance.py:1331} INFO - Starting attempt 1 of 2
[2025-03-02T19:06:57.466+0000] {taskinstance.py:1350} INFO - Executing <Task(PythonOperator): save_raw_station_details_information> on 2025-03-02 19:06:07.855037+00:00
[2025-03-02T19:06:57.473+0000] {standard_task_runner.py:57} INFO - Started process 42419 to run task
[2025-03-02T19:06:57.477+0000] {clientserver.py:543} INFO - Closing down clientserver connection
[2025-03-02T19:06:57.508+0000] {standard_task_runner.py:84} INFO - Running: ['***', 'tasks', 'run', 'api_to_db_dag', 'save_raw_station_details_information', 'manual__2025-03-02T19:06:07.855037+00:00', '--job-id', '169', '--raw', '--subdir', 'DAGS_FOLDER/dag.py', '--cfg-path', '/tmp/tmpk838_vg8']
[2025-03-02T19:06:57.511+0000] {standard_task_runner.py:85} INFO - Job 169: Subtask save_raw_station_details_information
[2025-03-02T19:06:57.579+0000] {task_command.py:410} INFO - Running <TaskInstance: api_to_db_dag.save_raw_station_details_information manual__2025-03-02T19:06:07.855037+00:00 [running]> on host 3befbd719c1b
[2025-03-02T19:06:57.722+0000] {taskinstance.py:1570} INFO - Exporting env vars: AIRFLOW_CTX_DAG_OWNER='***' AIRFLOW_CTX_DAG_ID='api_to_db_dag' AIRFLOW_CTX_TASK_ID='save_raw_station_details_information' AIRFLOW_CTX_EXECUTION_DATE='2025-03-02T19:06:07.855037+00:00' AIRFLOW_CTX_TRY_NUMBER='1' AIRFLOW_CTX_DAG_RUN_ID='manual__2025-03-02T19:06:07.855037+00:00'
[2025-03-02T19:06:57.938+0000] {clientserver.py:505} INFO - Error while sending or receiving.
Traceback (most recent call last):
  File "/home/airflow/.local/lib/python3.7/site-packages/py4j/clientserver.py", line 503, in send_command
    self.socket.sendall(command.encode("utf-8"))
ConnectionResetError: [Errno 104] Connection reset by peer
[2025-03-02T19:06:57.955+0000] {clientserver.py:543} INFO - Closing down clientserver connection
[2025-03-02T19:06:57.956+0000] {java_gateway.py:1052} INFO - Exception while sending command.
Traceback (most recent call last):
  File "/home/airflow/.local/lib/python3.7/site-packages/py4j/clientserver.py", line 503, in send_command
    self.socket.sendall(command.encode("utf-8"))
ConnectionResetError: [Errno 104] Connection reset by peer

During handling of the above exception, another exception occurred:

Traceback (most recent call last):
  File "/home/airflow/.local/lib/python3.7/site-packages/py4j/java_gateway.py", line 1038, in send_command
    response = connection.send_command(command)
  File "/home/airflow/.local/lib/python3.7/site-packages/py4j/clientserver.py", line 507, in send_command
    "Error while sending", e, proto.ERROR_ON_SEND)
py4j.protocol.Py4JNetworkError: Error while sending
[2025-03-02T19:06:57.977+0000] {clientserver.py:543} INFO - Closing down clientserver connection
[2025-03-02T19:06:57.982+0000] {datalake_saver.py:45} INFO - Data saved successfully to /mnt/data/raw/velib_api/station_information/20250302/202503021906.json
[2025-03-02T19:06:57.986+0000] {python.py:183} INFO - Done. Returned value was: /mnt/data/raw/velib_api/station_information/20250302/202503021906.json
[2025-03-02T19:06:58.154+0000] {taskinstance.py:1373} INFO - Marking task as SUCCESS. dag_id=api_to_db_dag, task_id=save_raw_station_details_information, execution_date=20250302T190607, start_date=20250302T190657, end_date=20250302T190658
[2025-03-02T19:06:58.251+0000] {local_task_job_runner.py:232} INFO - Task exited with return code 0
[2025-03-02T19:06:58.389+0000] {taskinstance.py:2674} INFO - 0 downstream tasks scheduled from follow-on schedule check
