[2025-02-28T14:13:51.803+0000] {taskinstance.py:1125} INFO - Dependencies all met for dep_context=non-requeueable deps ti=<TaskInstance: api_to_db_dag.save_station_information manual__2025-02-28T14:13:40.619450+00:00 [queued]>
[2025-02-28T14:13:51.810+0000] {taskinstance.py:1125} INFO - Dependencies all met for dep_context=requeueable deps ti=<TaskInstance: api_to_db_dag.save_station_information manual__2025-02-28T14:13:40.619450+00:00 [queued]>
[2025-02-28T14:13:51.810+0000] {taskinstance.py:1331} INFO - Starting attempt 1 of 1
[2025-02-28T14:13:51.820+0000] {taskinstance.py:1350} INFO - Executing <Task(PythonOperator): save_station_information> on 2025-02-28 14:13:40.619450+00:00
[2025-02-28T14:13:51.826+0000] {standard_task_runner.py:57} INFO - Started process 2004 to run task
[2025-02-28T14:13:51.826+0000] {clientserver.py:543} INFO - Closing down clientserver connection
[2025-02-28T14:13:51.830+0000] {standard_task_runner.py:84} INFO - Running: ['***', 'tasks', 'run', 'api_to_db_dag', 'save_station_information', 'manual__2025-02-28T14:13:40.619450+00:00', '--job-id', '7', '--raw', '--subdir', 'DAGS_FOLDER/dag.py', '--cfg-path', '/tmp/tmp3oqeusw2']
[2025-02-28T14:13:51.833+0000] {standard_task_runner.py:85} INFO - Job 7: Subtask save_station_information
[2025-02-28T14:13:51.853+0000] {clientserver.py:505} INFO - Error while sending or receiving.
Traceback (most recent call last):
  File "/home/airflow/.local/lib/python3.7/site-packages/py4j/clientserver.py", line 503, in send_command
    self.socket.sendall(command.encode("utf-8"))
ConnectionResetError: [Errno 104] Connection reset by peer
[2025-02-28T14:13:51.865+0000] {clientserver.py:543} INFO - Closing down clientserver connection
[2025-02-28T14:13:51.867+0000] {java_gateway.py:1052} INFO - Exception while sending command.
Traceback (most recent call last):
  File "/home/airflow/.local/lib/python3.7/site-packages/py4j/clientserver.py", line 503, in send_command
    self.socket.sendall(command.encode("utf-8"))
ConnectionResetError: [Errno 104] Connection reset by peer

During handling of the above exception, another exception occurred:

Traceback (most recent call last):
  File "/home/airflow/.local/lib/python3.7/site-packages/py4j/java_gateway.py", line 1038, in send_command
    response = connection.send_command(command)
  File "/home/airflow/.local/lib/python3.7/site-packages/py4j/clientserver.py", line 507, in send_command
    "Error while sending", e, proto.ERROR_ON_SEND)
py4j.protocol.Py4JNetworkError: Error while sending
[2025-02-28T14:13:51.871+0000] {clientserver.py:543} INFO - Closing down clientserver connection
[2025-02-28T14:13:51.892+0000] {task_command.py:410} INFO - Running <TaskInstance: api_to_db_dag.save_station_information manual__2025-02-28T14:13:40.619450+00:00 [running]> on host 2e469bce1432
[2025-02-28T14:13:51.955+0000] {taskinstance.py:1570} INFO - Exporting env vars: AIRFLOW_CTX_DAG_OWNER='***' AIRFLOW_CTX_DAG_ID='api_to_db_dag' AIRFLOW_CTX_TASK_ID='save_station_information' AIRFLOW_CTX_EXECUTION_DATE='2025-02-28T14:13:40.619450+00:00' AIRFLOW_CTX_TRY_NUMBER='1' AIRFLOW_CTX_DAG_RUN_ID='manual__2025-02-28T14:13:40.619450+00:00'
[2025-02-28T14:13:52.089+0000] {python.py:183} INFO - Done. Returned value was: /mnt/data/raw/velib_api/velib_stations/20250228/202502281413.json
[2025-02-28T14:13:52.142+0000] {taskinstance.py:1373} INFO - Marking task as SUCCESS. dag_id=api_to_db_dag, task_id=save_station_information, execution_date=20250228T141340, start_date=20250228T141351, end_date=20250228T141352
[2025-02-28T14:13:52.186+0000] {local_task_job_runner.py:232} INFO - Task exited with return code 0
[2025-02-28T14:13:52.207+0000] {taskinstance.py:2674} INFO - 1 downstream tasks scheduled from follow-on schedule check
